<?xml version="1.0" encoding="utf-8"?>
<!-- This URDF was automatically created by SolidWorks to URDF Exporter! Originally created by Stephen Brawner (brawner@gmail.com) 
     Commit Version: 1.6.0-1-g15f4949  Build Version: 1.6.7594.29634
     For more information, please see http://wiki.ros.org/sw_urdf_exporter -->
<robot
  name="Car_1">
  <link name="Dummy"/>
  <link
    name="Chassis">
    <inertial>
      <origin
        xyz="9.85359198453595E-05 -0.016463414418635 -1.61805565512309E-16"
        rpy="0 0 0" />
      <mass
        value="161.904412309527" />
      <inertia
        ixx="22.6226623674723"
        ixy="-0.00106031744847904"
        ixz="1.94916551280363E-15"
        iyy="63.2906242505968"
        iyz="1.17745429693053E-15"
        izz="41.2716349546351" />
    </inertial>
    <visual>
      <origin
        xyz="0 0 0"
        rpy="0 0 0" />
      <geometry>
        <mesh
          filename="package://Car_1/meshes/Chassis.STL" />
      </geometry>
      <material
        name="">
        <color
          rgba="0.792156862745098 0.819607843137255 0.933333333333333 1" />
      </material>
    </visual>
    <collision>
      <origin
        xyz="0 0 0"
        rpy="0 0 0" />
      <geometry>
        <mesh
          filename="package://Car_1/meshes/Chassis.STL" />
      </geometry>
    </collision>
  </link>
  <joint
    name="Dummy_Chassis_Joint"
    type="fixed">
    <parent
      link="Dummy" />
    <child
      link="Chassis" />
  </joint>
  <link
    name="FL_Wheel">
    <inertial>
      <origin
        xyz="0 0 0.378081044321113"
        rpy="0 0 0" />
      <mass
        value="16.4704899135177" />
      <inertia
        ixx="0.170899521278999"
        ixy="0"
        ixz="-3.38657707334201E-18"
        iyy="0.170899521278999"
        iyz="-5.98392577789642E-19"
        izz="0.173579729077305" />
    </inertial>
    <visual>
      <origin
        xyz="0 0 0"
        rpy="0 0 0" />
      <geometry>
        <mesh
          filename="package://Car_1/meshes/FL_Wheel.STL" />
      </geometry>
      <material
        name="">
        <color
          rgba="0.792156862745098 0.819607843137255 0.933333333333333 1" />
      </material>
    </visual>
    <collision>
      <origin
        xyz="0 0 0"
        rpy="0 0 0" />
      <geometry>
        <mesh
          filename="package://Car_1/meshes/FL_Wheel.STL" />
      </geometry>
    </collision>
  </link>
  <joint
    name="FLW_Chassis"
    type="revolute">
    <origin
      xyz="-0.6 0.35 -0.025"
      rpy="1.5708 0.39309 -3.1416" />
    <parent
      link="Chassis" />
    <child
      link="FL_Wheel" />
    <axis
      xyz="0 0 1" />
    <limit
      lower="-1000000"
      upper="1000000"
      effort="100"
      velocity="1000" />
  </joint>
  <transmission name="FL_Wheel_Trans">
    <type>transmission_interface/SimpleTransmission</type>
    <joint name="FLW_Chassis">
      <hardwareInterface>hardware_interface/VelocityJointInterface</hardwareInterface>
    </joint>
    <actuator name="FLW_Motor">
      <hardwareInterface>hardware_interface/VelocityJointInterface</hardwareInterface>
      <mechanicalReduction>1</mechanicalReduction>
    </actuator>
  </transmission>
  <link
    name="FR_Wheel">
    <inertial>
      <origin
        xyz="0 -3.46944695195361E-18 0.378081044321113"
        rpy="0 0 0" />
      <mass
        value="16.4704899135177" />
      <inertia
        ixx="0.170899521278999"
        ixy="-1.17094433004118E-34"
        ixz="-3.84287660115048E-18"
        iyy="0.170899521278999"
        iyz="-1.03780467368306E-34"
        izz="0.173579729077305" />
    </inertial>
    <visual>
      <origin
        xyz="0 0 0"
        rpy="0 0 0" />
      <geometry>
        <mesh
          filename="package://Car_1/meshes/FR_Wheel.STL" />
      </geometry>
      <material
        name="">
        <color
          rgba="0.792156862745098 0.819607843137255 0.933333333333333 1" />
      </material>
    </visual>
    <collision>
      <origin
        xyz="0 0 0"
        rpy="0 0 0" />
      <geometry>
        <mesh
          filename="package://Car_1/meshes/FR_Wheel.STL" />
      </geometry>
    </collision>
  </link>
  <joint
    name="FRW_Chassis"
    type="revolute">
    <origin
      xyz="-0.6 -0.35 -0.025"
      rpy="1.5708 0 0" />
    <parent
      link="Chassis" />
    <child
      link="FR_Wheel" />
    <axis
      xyz="0 0 1" />
    <limit
      lower="-1000000"
      upper="1000000"
      effort="100"
      velocity="1000" />
  </joint>
  <transmission name="FR_Wheel_Trans">
    <type>transmission_interface/SimpleTransmission</type>
    <joint name="FRW_Chassis">
      <hardwareInterface>hardware_interface/VelocityJointInterface</hardwareInterface>
    </joint>
    <actuator name="FRW_Motor">
      <hardwareInterface>hardware_interface/VelocityJointInterface</hardwareInterface>
      <mechanicalReduction>1</mechanicalReduction>
    </actuator>
  </transmission>
  <link
    name="RL_Wheel">
    <inertial>
      <origin
        xyz="0 0 0.378081044321113"
        rpy="0 0 0" />
      <mass
        value="16.4704899135177" />
      <inertia
        ixx="0.170899521278999"
        ixy="0"
        ixz="-3.38657707334201E-18"
        iyy="0.170899521278999"
        iyz="-5.98392577789642E-19"
        izz="0.173579729077305" />
    </inertial>
    <visual>
      <origin
        xyz="0 0 0"
        rpy="0 0 0" />
      <geometry>
        <mesh
          filename="package://Car_1/meshes/RL_Wheel.STL" />
      </geometry>
      <material
        name="">
        <color
          rgba="0.792156862745098 0.819607843137255 0.933333333333333 1" />
      </material>
    </visual>
    <collision>
      <origin
        xyz="0 0 0"
        rpy="0 0 0" />
      <geometry>
        <mesh
          filename="package://Car_1/meshes/RL_Wheel.STL" />
      </geometry>
    </collision>
  </link>
  <joint
    name="RLW_Chassis"
    type="revolute">
    <origin
      xyz="0.6 0.35 -0.025"
      rpy="1.5708 0.39309 -3.1416" />
    <parent
      link="Chassis" />
    <child
      link="RL_Wheel" />
    <axis
      xyz="0 0 1" />
    <limit
      lower="-1000000"
      upper="1000000"
      effort="100"
      velocity="1000" />
  </joint>
  <transmission name="RL_Wheel_Trans">
    <type>transmission_interface/SimpleTransmission</type>
    <joint name="RLW_Chassis">
      <hardwareInterface>hardware_interface/VelocityJointInterface</hardwareInterface>
    </joint>
    <actuator name="RLW_Motor">
      <hardwareInterface>hardware_interface/VelocityJointInterface</hardwareInterface>
      <mechanicalReduction>1</mechanicalReduction>
    </actuator>
  </transmission>
  <link
    name="RR_Wheel">
    <inertial>
      <origin
        xyz="0 -3.46944695195361E-18 0.378081044321113"
        rpy="0 0 0" />
      <mass
        value="16.4704899135177" />
      <inertia
        ixx="0.170899521278999"
        ixy="-1.17094433004118E-34"
        ixz="-3.84287660115048E-18"
        iyy="0.170899521278999"
        iyz="-1.03780467368306E-34"
        izz="0.173579729077305" />
    </inertial>
    <visual>
      <origin
        xyz="0 0 0"
        rpy="0 0 0" />
      <geometry>
        <mesh
          filename="package://Car_1/meshes/RR_Wheel.STL" />
      </geometry>
      <material
        name="">
        <color
          rgba="0.792156862745098 0.819607843137255 0.933333333333333 1" />
      </material>
    </visual>
    <collision>
      <origin
        xyz="0 0 0"
        rpy="0 0 0" />
      <geometry>
        <mesh
          filename="package://Car_1/meshes/RR_Wheel.STL" />
      </geometry>
    </collision>
  </link>
  <joint
    name="RRW_Chassis"
    type="revolute">
    <origin
      xyz="0.6 -0.35 -0.025"
      rpy="1.5708 0 0" />
    <parent
      link="Chassis" />
    <child
      link="RR_Wheel" />
    <axis
      xyz="0 0 1" />
    <limit
      lower="-1000000"
      upper="1000000"
      effort="100"
      velocity="1000" />
  </joint>
  <transmission name="RR_Wheel_Trans">
    <type>transmission_interface/SimpleTransmission</type>
    <joint name="RRW_Chassis">
      <hardwareInterface>hardware_interface/VelocityJointInterface</hardwareInterface>
    </joint>
    <actuator name="RRW_Motor">
      <hardwareInterface>hardware_interface/VelocityJointInterface</hardwareInterface>
      <mechanicalReduction>1</mechanicalReduction>
    </actuator>
  </transmission>
  <link
    name="Arm_Base">
    <inertial>
      <origin
        xyz="0 0.152976096204713 1.50309365625096E-18"
        rpy="0 0 0" />
      <mass
        value="3.25348441268186" />
      <inertia
        ixx="0.0195880123660322"
        ixy="2.51212011347482E-19"
        ixz="1.81752260093214E-17"
        iyy="0.0075081587745099"
        iyz="4.21274880646901E-19"
        izz="0.0192954745601843" />
    </inertial>
    <visual>
      <origin
        xyz="0 0 0"
        rpy="0 0 0" />
      <geometry>
        <mesh
          filename="package://Car_1/meshes/Arm_Base.STL" />
      </geometry>
      <material
        name="">
        <color
          rgba="0.792156862745098 0.819607843137255 0.933333333333333 1" />
      </material>
    </visual>
    <collision>
      <origin
        xyz="0 0 0"
        rpy="0 0 0" />
      <geometry>
        <mesh
          filename="package://Car_1/meshes/Arm_Base.STL" />
      </geometry>
    </collision>
  </link>
  <joint
    name="AB_Chassis"
    type="revolute">
    <origin
      xyz="-0.65 0 0.025"
      rpy="1.5708 0 0" />
    <parent
      link="Chassis" />
    <child
      link="Arm_Base" />
    <axis
      xyz="0 1 0" />
    <limit
      lower="-2.8973"
      upper="2.8973"
      effort="87"
      velocity="2.1750" />
  </joint>
  <transmission name="Arm_Base_Trans">
    <type>transmission_interface/SimpleTransmission</type>
    <joint name="AB_Chassis">
      <hardwareInterface>hardware_interface/PositionJointInterface</hardwareInterface>
    </joint>
    <actuator name="AB_Motor">
      <hardwareInterface>hardware_interface/PositionJointInterface</hardwareInterface>
      <mechanicalReduction>1</mechanicalReduction>
    </actuator>
  </transmission>
  <link
    name="Bicep">
    <inertial>
      <origin
        xyz="-1.11022302462516E-16 0.205 4.03161623391747E-08"
        rpy="0 0 0" />
      <mass
        value="5.01050096511363" />
      <inertia
        ixx="0.0709872630145202"
        ixy="-6.28898095202147E-08"
        ixz="3.96116733721931E-19"
        iyy="0.0149239034213916"
        iyz="-2.34671088771049E-18"
        izz="0.0636472439734091" />
    </inertial>
    <visual>
      <origin
        xyz="0 0 0"
        rpy="0 0 0" />
      <geometry>
        <mesh
          filename="package://Car_1/meshes/Bicep.STL" />
      </geometry>
      <material
        name="">
        <color
          rgba="0.792156862745098 0.819607843137255 0.933333333333333 1" />
      </material>
    </visual>
    <collision>
      <origin
        xyz="0 0 0"
        rpy="0 0 0" />
      <geometry>
        <mesh
          filename="package://Car_1/meshes/Bicep.STL" />
      </geometry>
    </collision>
  </link>
  <joint
    name="Bicep_AB"
    type="revolute">
    <origin
      xyz="0 0.25 0"
      rpy="0 0 0" />
    <parent
      link="Arm_Base" />
    <child
      link="Bicep" />
    <axis
      xyz="0 0 1" />
    <limit
      lower="-1.7628"
      upper="1.7628"
      effort="87"
      velocity="2.1750" />
  </joint>
  <transmission name="Bicep_Trans">
    <type>transmission_interface/SimpleTransmission</type>
    <joint name="Bicep_AB">
      <hardwareInterface>hardware_interface/PositionJointInterface</hardwareInterface>
    </joint>
    <actuator name="Bicep_Motor">
      <hardwareInterface>hardware_interface/PositionJointInterface</hardwareInterface>
      <mechanicalReduction>1</mechanicalReduction>
    </actuator>
  </transmission>
  <link
    name="Bottom_Wrist">
    <inertial>
      <origin
        xyz="-5.76005539931757E-08 0.104723859303367 6.29756783574483E-05"
        rpy="0 0 0" />
      <mass
        value="3.06244303749571" />
      <inertia
        ixx="0.0242070590575506"
        ixy="3.29905354266355E-08"
        ixz="-1.66452981213341E-09"
        iyy="0.00557103438969488"
        iyz="-5.93643774158451E-06"
        izz="0.0236179659392289" />
    </inertial>
    <visual>
      <origin
        xyz="0 0 0"
        rpy="0 0 0" />
      <geometry>
        <mesh
          filename="package://Car_1/meshes/Bottom_Wrist.STL" />
      </geometry>
      <material
        name="">
        <color
          rgba="0.792156862745098 0.819607843137255 0.933333333333333 1" />
      </material>
    </visual>
    <collision>
      <origin
        xyz="0 0 0"
        rpy="0 0 0" />
      <geometry>
        <mesh
          filename="package://Car_1/meshes/Bottom_Wrist.STL" />
      </geometry>
    </collision>
  </link>
  <joint
    name="BW_Bicep"
    type="revolute">
    <origin
      xyz="0 0.41 0"
      rpy="0 0 0" />
    <parent
      link="Bicep" />
    <child
      link="Bottom_Wrist" />
    <axis
      xyz="0 0 1" />
    <limit
      lower="-1.7628"
      upper="1.7628"
      effort="87"
      velocity="2.1750" />
  </joint>
  <transmission name="Bottom_Wrist_Trans">
    <type>transmission_interface/SimpleTransmission</type>
    <joint name="BW_Bicep">
      <hardwareInterface>hardware_interface/PositionJointInterface</hardwareInterface>
    </joint>
    <actuator name="BW_Motor">
      <hardwareInterface>hardware_interface/PositionJointInterface</hardwareInterface>
      <mechanicalReduction>1</mechanicalReduction>
    </actuator>
  </transmission>
  <link
    name="Elbow">
    <inertial>
      <origin
        xyz="1.0222248303382E-07 0.260839568533626 -6.72505269797146E-10"
        rpy="0 0 0" />
      <mass
        value="4.78140114383765" />
      <inertia
        ixx="0.0576162597068767"
        ixy="-3.90344857447567E-08"
        ixz="1.91474307365374E-09"
        iyy="0.0134139330355465"
        iyz="-9.38952159160228E-12"
        izz="0.0516557926060428" />
    </inertial>
    <visual>
      <origin
        xyz="0 0 0"
        rpy="0 0 0" />
      <geometry>
        <mesh
          filename="package://Car_1/meshes/Elbow.STL" />
      </geometry>
      <material
        name="">
        <color
          rgba="0.792156862745098 0.819607843137255 0.933333333333333 1" />
      </material>
    </visual>
    <collision>
      <origin
        xyz="0 0 0"
        rpy="0 0 0" />
      <geometry>
        <mesh
          filename="package://Car_1/meshes/Elbow.STL" />
      </geometry>
    </collision>
  </link>
  <joint
    name="Elbow_BW"
    type="revolute">
    <origin
      xyz="0 0.15 0"
      rpy="0 0 0" />
    <parent
      link="Bottom_Wrist" />
    <child
      link="Elbow" />
    <axis
      xyz="0 1 0" />
    <limit
      lower="-1.7628"
      upper="1.7628"
      effort="87"
      velocity="2.1750" />
  </joint>
  <transmission name="Elbow_Trans">
    <type>transmission_interface/SimpleTransmission</type>
    <joint name="Elbow_BW">
      <hardwareInterface>hardware_interface/PositionJointInterface</hardwareInterface>
    </joint>
    <actuator name="Elbow_Motor">
      <hardwareInterface>hardware_interface/PositionJointInterface</hardwareInterface>
      <mechanicalReduction>1</mechanicalReduction>
    </actuator>
  </transmission>
  <link
    name="Top_Wrist">
    <inertial>
      <origin
        xyz="-5.76005539931757E-08 0.104723859303367 6.29756783574647E-05"
        rpy="0 0 0" />
      <mass
        value="3.06244303749571" />
      <inertia
        ixx="0.0242070590575507"
        ixy="3.29905354340545E-08"
        ixz="-1.66452981111517E-09"
        iyy="0.00557103438969488"
        iyz="-5.9364377415831E-06"
        izz="0.023617965939229" />
    </inertial>
    <visual>
      <origin
        xyz="0 0 0"
        rpy="0 0 0" />
      <geometry>
        <mesh
          filename="package://Car_1/meshes/Top_Wrist.STL" />
      </geometry>
      <material
        name="">
        <color
          rgba="0.792156862745098 0.819607843137255 0.933333333333333 1" />
      </material>
    </visual>
    <collision>
      <origin
        xyz="0 0 0"
        rpy="0 0 0" />
      <geometry>
        <mesh
          filename="package://Car_1/meshes/Top_Wrist.STL" />
      </geometry>
    </collision>
  </link>
  <joint
    name="TW_Elbow"
    type="revolute">
    <origin
      xyz="0 0.455 0"
      rpy="0 0 0" />
    <parent
      link="Elbow" />
    <child
      link="Top_Wrist" />
    <axis
      xyz="0 0 1" />
    <limit
      lower="-1.7628"
      upper="1.7628"
      effort="87"
      velocity="2.1750" />
  </joint>
  <link name = "End_Effector" />
  <joint name="EE_TW" type="fixed">
    <parent link="Top_Wrist" />
    <child link="End_Effector" />
  </joint>
  <transmission name="Top_Wrist_Trans">
    <type>transmission_interface/SimpleTransmission</type>
    <joint name="TW_Elbow">
      <hardwareInterface>hardware_interface/PositionJointInterface</hardwareInterface>
    </joint>
    <actuator name="TW_Motor">
      <hardwareInterface>hardware_interface/PositionJointInterface</hardwareInterface>
      <mechanicalReduction>1</mechanicalReduction>
    </actuator>
  </transmission>
</robot>